Backup failed for Site dcode.com. Database or site_config.json may be corrupted
Traceback (most recent call last):
  File "apps/frappe/frappe/commands/site.py", line 592, in backup
    odb = scheduled_backup(
  File "apps/frappe/frappe/utils/backups.py", line 504, in scheduled_backup
    odb = new_backup(
  File "apps/frappe/frappe/utils/backups.py", line 538, in new_backup
    odb = BackupGenerator(
  File "apps/frappe/frappe/utils/backups.py", line 85, in __init__
    self.setup_backup_tables()
  File "apps/frappe/frappe/utils/backups.py", line 119, in setup_backup_tables
    existing_doctypes = set([x.name for x in frappe.get_all("DocType")])
  File "apps/frappe/frappe/__init__.py", line 1758, in get_all
    return get_list(doctype, *args, **kwargs)
  File "apps/frappe/frappe/__init__.py", line 1730, in get_list
    return frappe.model.db_query.DatabaseQuery(doctype).execute(*args, **kwargs)
  File "apps/frappe/frappe/model/db_query.py", line 167, in execute
    self.columns = self.get_table_columns()
  File "apps/frappe/frappe/model/db_query.py", line 441, in get_table_columns
    return get_table_columns(self.doctype)
  File "apps/frappe/frappe/model/meta.py", line 63, in get_table_columns
    return frappe.db.get_table_columns(doctype)
  File "apps/frappe/frappe/database/database.py", line 1091, in get_table_columns
    columns = self.get_db_table_columns("tab" + doctype)
  File "apps/frappe/frappe/database/database.py", line 1075, in get_db_table_columns
    for r in self.sql(
  File "apps/frappe/frappe/database/database.py", line 161, in sql
    self.connect()
  File "apps/frappe/frappe/database/database.py", line 85, in connect
    self._conn = self.get_connection()
  File "apps/frappe/frappe/database/mariadb/database.py", line 76, in get_connection
    conn = pymysql.connect(
  File "env/lib/python3.8/site-packages/pymysql/connections.py", line 353, in __init__
    self.connect()
  File "env/lib/python3.8/site-packages/pymysql/connections.py", line 633, in connect
    self._request_authentication()
  File "env/lib/python3.8/site-packages/pymysql/connections.py", line 907, in _request_authentication
    auth_packet = self._read_packet()
  File "env/lib/python3.8/site-packages/pymysql/connections.py", line 725, in _read_packet
    packet.raise_for_error()
  File "env/lib/python3.8/site-packages/pymysql/protocol.py", line 221, in raise_for_error
    err.raise_mysql_exception(self._data)
  File "env/lib/python3.8/site-packages/pymysql/err.py", line 143, in raise_mysql_exception
    raise errorclass(errno, errval)
pymysql.err.OperationalError: (1045, "Access denied for user '_4859f2df50354e92'@'localhost' (using password: YES)")

Backup failed for Site ivm.com. Database or site_config.json may be corrupted
Traceback (most recent call last):
  File "apps/frappe/frappe/commands/site.py", line 592, in backup
    odb = scheduled_backup(
  File "apps/frappe/frappe/utils/backups.py", line 504, in scheduled_backup
    odb = new_backup(
  File "apps/frappe/frappe/utils/backups.py", line 538, in new_backup
    odb = BackupGenerator(
  File "apps/frappe/frappe/utils/backups.py", line 85, in __init__
    self.setup_backup_tables()
  File "apps/frappe/frappe/utils/backups.py", line 119, in setup_backup_tables
    existing_doctypes = set([x.name for x in frappe.get_all("DocType")])
  File "apps/frappe/frappe/__init__.py", line 1758, in get_all
    return get_list(doctype, *args, **kwargs)
  File "apps/frappe/frappe/__init__.py", line 1730, in get_list
    return frappe.model.db_query.DatabaseQuery(doctype).execute(*args, **kwargs)
  File "apps/frappe/frappe/model/db_query.py", line 167, in execute
    self.columns = self.get_table_columns()
  File "apps/frappe/frappe/model/db_query.py", line 441, in get_table_columns
    return get_table_columns(self.doctype)
  File "apps/frappe/frappe/model/meta.py", line 63, in get_table_columns
    return frappe.db.get_table_columns(doctype)
  File "apps/frappe/frappe/database/database.py", line 1091, in get_table_columns
    columns = self.get_db_table_columns("tab" + doctype)
  File "apps/frappe/frappe/database/database.py", line 1075, in get_db_table_columns
    for r in self.sql(
  File "apps/frappe/frappe/database/database.py", line 161, in sql
    self.connect()
  File "apps/frappe/frappe/database/database.py", line 85, in connect
    self._conn = self.get_connection()
  File "apps/frappe/frappe/database/mariadb/database.py", line 76, in get_connection
    conn = pymysql.connect(
  File "env/lib/python3.8/site-packages/pymysql/connections.py", line 353, in __init__
    self.connect()
  File "env/lib/python3.8/site-packages/pymysql/connections.py", line 633, in connect
    self._request_authentication()
  File "env/lib/python3.8/site-packages/pymysql/connections.py", line 907, in _request_authentication
    auth_packet = self._read_packet()
  File "env/lib/python3.8/site-packages/pymysql/connections.py", line 725, in _read_packet
    packet.raise_for_error()
  File "env/lib/python3.8/site-packages/pymysql/protocol.py", line 221, in raise_for_error
    err.raise_mysql_exception(self._data)
  File "env/lib/python3.8/site-packages/pymysql/err.py", line 143, in raise_mysql_exception
    raise errorclass(errno, errval)
pymysql.err.OperationalError: (1045, "Access denied for user '_4859f2df50354e92'@'localhost' (using password: YES)")

Backup failed for Site site1.local. Database or site_config.json may be corrupted
Traceback (most recent call last):
  File "apps/frappe/frappe/commands/site.py", line 592, in backup
    odb = scheduled_backup(
  File "apps/frappe/frappe/utils/backups.py", line 504, in scheduled_backup
    odb = new_backup(
  File "apps/frappe/frappe/utils/backups.py", line 538, in new_backup
    odb = BackupGenerator(
  File "apps/frappe/frappe/utils/backups.py", line 85, in __init__
    self.setup_backup_tables()
  File "apps/frappe/frappe/utils/backups.py", line 119, in setup_backup_tables
    existing_doctypes = set([x.name for x in frappe.get_all("DocType")])
  File "apps/frappe/frappe/__init__.py", line 1758, in get_all
    return get_list(doctype, *args, **kwargs)
  File "apps/frappe/frappe/__init__.py", line 1730, in get_list
    return frappe.model.db_query.DatabaseQuery(doctype).execute(*args, **kwargs)
  File "apps/frappe/frappe/model/db_query.py", line 167, in execute
    self.columns = self.get_table_columns()
  File "apps/frappe/frappe/model/db_query.py", line 441, in get_table_columns
    return get_table_columns(self.doctype)
  File "apps/frappe/frappe/model/meta.py", line 63, in get_table_columns
    return frappe.db.get_table_columns(doctype)
  File "apps/frappe/frappe/database/database.py", line 1091, in get_table_columns
    columns = self.get_db_table_columns("tab" + doctype)
  File "apps/frappe/frappe/database/database.py", line 1075, in get_db_table_columns
    for r in self.sql(
  File "apps/frappe/frappe/database/database.py", line 161, in sql
    self.connect()
  File "apps/frappe/frappe/database/database.py", line 85, in connect
    self._conn = self.get_connection()
  File "apps/frappe/frappe/database/mariadb/database.py", line 76, in get_connection
    conn = pymysql.connect(
  File "env/lib/python3.8/site-packages/pymysql/connections.py", line 353, in __init__
    self.connect()
  File "env/lib/python3.8/site-packages/pymysql/connections.py", line 633, in connect
    self._request_authentication()
  File "env/lib/python3.8/site-packages/pymysql/connections.py", line 907, in _request_authentication
    auth_packet = self._read_packet()
  File "env/lib/python3.8/site-packages/pymysql/connections.py", line 725, in _read_packet
    packet.raise_for_error()
  File "env/lib/python3.8/site-packages/pymysql/protocol.py", line 221, in raise_for_error
    err.raise_mysql_exception(self._data)
  File "env/lib/python3.8/site-packages/pymysql/err.py", line 143, in raise_mysql_exception
    raise errorclass(errno, errval)
pymysql.err.OperationalError: (1045, "Access denied for user '_4859f2df50354e92'@'localhost' (using password: YES)")

Backup failed for Site dcode.com. Database or site_config.json may be corrupted
Traceback (most recent call last):
  File "apps/frappe/frappe/commands/site.py", line 592, in backup
    odb = scheduled_backup(
  File "apps/frappe/frappe/utils/backups.py", line 504, in scheduled_backup
    odb = new_backup(
  File "apps/frappe/frappe/utils/backups.py", line 538, in new_backup
    odb = BackupGenerator(
  File "apps/frappe/frappe/utils/backups.py", line 85, in __init__
    self.setup_backup_tables()
  File "apps/frappe/frappe/utils/backups.py", line 119, in setup_backup_tables
    existing_doctypes = set([x.name for x in frappe.get_all("DocType")])
  File "apps/frappe/frappe/__init__.py", line 1758, in get_all
    return get_list(doctype, *args, **kwargs)
  File "apps/frappe/frappe/__init__.py", line 1730, in get_list
    return frappe.model.db_query.DatabaseQuery(doctype).execute(*args, **kwargs)
  File "apps/frappe/frappe/model/db_query.py", line 167, in execute
    self.columns = self.get_table_columns()
  File "apps/frappe/frappe/model/db_query.py", line 441, in get_table_columns
    return get_table_columns(self.doctype)
  File "apps/frappe/frappe/model/meta.py", line 63, in get_table_columns
    return frappe.db.get_table_columns(doctype)
  File "apps/frappe/frappe/database/database.py", line 1091, in get_table_columns
    columns = self.get_db_table_columns("tab" + doctype)
  File "apps/frappe/frappe/database/database.py", line 1075, in get_db_table_columns
    for r in self.sql(
  File "apps/frappe/frappe/database/database.py", line 161, in sql
    self.connect()
  File "apps/frappe/frappe/database/database.py", line 85, in connect
    self._conn = self.get_connection()
  File "apps/frappe/frappe/database/mariadb/database.py", line 76, in get_connection
    conn = pymysql.connect(
  File "env/lib/python3.8/site-packages/pymysql/connections.py", line 353, in __init__
    self.connect()
  File "env/lib/python3.8/site-packages/pymysql/connections.py", line 633, in connect
    self._request_authentication()
  File "env/lib/python3.8/site-packages/pymysql/connections.py", line 907, in _request_authentication
    auth_packet = self._read_packet()
  File "env/lib/python3.8/site-packages/pymysql/connections.py", line 725, in _read_packet
    packet.raise_for_error()
  File "env/lib/python3.8/site-packages/pymysql/protocol.py", line 221, in raise_for_error
    err.raise_mysql_exception(self._data)
  File "env/lib/python3.8/site-packages/pymysql/err.py", line 143, in raise_mysql_exception
    raise errorclass(errno, errval)
pymysql.err.OperationalError: (1045, "Access denied for user '_4859f2df50354e92'@'localhost' (using password: YES)")

Backup failed for Site ivm.com. Database or site_config.json may be corrupted
Traceback (most recent call last):
  File "apps/frappe/frappe/commands/site.py", line 592, in backup
    odb = scheduled_backup(
  File "apps/frappe/frappe/utils/backups.py", line 504, in scheduled_backup
    odb = new_backup(
  File "apps/frappe/frappe/utils/backups.py", line 538, in new_backup
    odb = BackupGenerator(
  File "apps/frappe/frappe/utils/backups.py", line 85, in __init__
    self.setup_backup_tables()
  File "apps/frappe/frappe/utils/backups.py", line 119, in setup_backup_tables
    existing_doctypes = set([x.name for x in frappe.get_all("DocType")])
  File "apps/frappe/frappe/__init__.py", line 1758, in get_all
    return get_list(doctype, *args, **kwargs)
  File "apps/frappe/frappe/__init__.py", line 1730, in get_list
    return frappe.model.db_query.DatabaseQuery(doctype).execute(*args, **kwargs)
  File "apps/frappe/frappe/model/db_query.py", line 167, in execute
    self.columns = self.get_table_columns()
  File "apps/frappe/frappe/model/db_query.py", line 441, in get_table_columns
    return get_table_columns(self.doctype)
  File "apps/frappe/frappe/model/meta.py", line 63, in get_table_columns
    return frappe.db.get_table_columns(doctype)
  File "apps/frappe/frappe/database/database.py", line 1091, in get_table_columns
    columns = self.get_db_table_columns("tab" + doctype)
  File "apps/frappe/frappe/database/database.py", line 1075, in get_db_table_columns
    for r in self.sql(
  File "apps/frappe/frappe/database/database.py", line 161, in sql
    self.connect()
  File "apps/frappe/frappe/database/database.py", line 85, in connect
    self._conn = self.get_connection()
  File "apps/frappe/frappe/database/mariadb/database.py", line 76, in get_connection
    conn = pymysql.connect(
  File "env/lib/python3.8/site-packages/pymysql/connections.py", line 353, in __init__
    self.connect()
  File "env/lib/python3.8/site-packages/pymysql/connections.py", line 633, in connect
    self._request_authentication()
  File "env/lib/python3.8/site-packages/pymysql/connections.py", line 907, in _request_authentication
    auth_packet = self._read_packet()
  File "env/lib/python3.8/site-packages/pymysql/connections.py", line 725, in _read_packet
    packet.raise_for_error()
  File "env/lib/python3.8/site-packages/pymysql/protocol.py", line 221, in raise_for_error
    err.raise_mysql_exception(self._data)
  File "env/lib/python3.8/site-packages/pymysql/err.py", line 143, in raise_mysql_exception
    raise errorclass(errno, errval)
pymysql.err.OperationalError: (1045, "Access denied for user '_4859f2df50354e92'@'localhost' (using password: YES)")

Backup failed for Site site1.local. Database or site_config.json may be corrupted
Traceback (most recent call last):
  File "apps/frappe/frappe/commands/site.py", line 592, in backup
    odb = scheduled_backup(
  File "apps/frappe/frappe/utils/backups.py", line 504, in scheduled_backup
    odb = new_backup(
  File "apps/frappe/frappe/utils/backups.py", line 538, in new_backup
    odb = BackupGenerator(
  File "apps/frappe/frappe/utils/backups.py", line 85, in __init__
    self.setup_backup_tables()
  File "apps/frappe/frappe/utils/backups.py", line 119, in setup_backup_tables
    existing_doctypes = set([x.name for x in frappe.get_all("DocType")])
  File "apps/frappe/frappe/__init__.py", line 1758, in get_all
    return get_list(doctype, *args, **kwargs)
  File "apps/frappe/frappe/__init__.py", line 1730, in get_list
    return frappe.model.db_query.DatabaseQuery(doctype).execute(*args, **kwargs)
  File "apps/frappe/frappe/model/db_query.py", line 167, in execute
    self.columns = self.get_table_columns()
  File "apps/frappe/frappe/model/db_query.py", line 441, in get_table_columns
    return get_table_columns(self.doctype)
  File "apps/frappe/frappe/model/meta.py", line 63, in get_table_columns
    return frappe.db.get_table_columns(doctype)
  File "apps/frappe/frappe/database/database.py", line 1091, in get_table_columns
    columns = self.get_db_table_columns("tab" + doctype)
  File "apps/frappe/frappe/database/database.py", line 1075, in get_db_table_columns
    for r in self.sql(
  File "apps/frappe/frappe/database/database.py", line 161, in sql
    self.connect()
  File "apps/frappe/frappe/database/database.py", line 85, in connect
    self._conn = self.get_connection()
  File "apps/frappe/frappe/database/mariadb/database.py", line 76, in get_connection
    conn = pymysql.connect(
  File "env/lib/python3.8/site-packages/pymysql/connections.py", line 353, in __init__
    self.connect()
  File "env/lib/python3.8/site-packages/pymysql/connections.py", line 633, in connect
    self._request_authentication()
  File "env/lib/python3.8/site-packages/pymysql/connections.py", line 907, in _request_authentication
    auth_packet = self._read_packet()
  File "env/lib/python3.8/site-packages/pymysql/connections.py", line 725, in _read_packet
    packet.raise_for_error()
  File "env/lib/python3.8/site-packages/pymysql/protocol.py", line 221, in raise_for_error
    err.raise_mysql_exception(self._data)
  File "env/lib/python3.8/site-packages/pymysql/err.py", line 143, in raise_mysql_exception
    raise errorclass(errno, errval)
pymysql.err.OperationalError: (1045, "Access denied for user '_4859f2df50354e92'@'localhost' (using password: YES)")

Backup failed for Site dcode.com. Database or site_config.json may be corrupted
Traceback (most recent call last):
  File "apps/frappe/frappe/commands/site.py", line 592, in backup
    odb = scheduled_backup(
  File "apps/frappe/frappe/utils/backups.py", line 504, in scheduled_backup
    odb = new_backup(
  File "apps/frappe/frappe/utils/backups.py", line 538, in new_backup
    odb = BackupGenerator(
  File "apps/frappe/frappe/utils/backups.py", line 85, in __init__
    self.setup_backup_tables()
  File "apps/frappe/frappe/utils/backups.py", line 119, in setup_backup_tables
    existing_doctypes = set([x.name for x in frappe.get_all("DocType")])
  File "apps/frappe/frappe/__init__.py", line 1758, in get_all
    return get_list(doctype, *args, **kwargs)
  File "apps/frappe/frappe/__init__.py", line 1730, in get_list
    return frappe.model.db_query.DatabaseQuery(doctype).execute(*args, **kwargs)
  File "apps/frappe/frappe/model/db_query.py", line 167, in execute
    self.columns = self.get_table_columns()
  File "apps/frappe/frappe/model/db_query.py", line 441, in get_table_columns
    return get_table_columns(self.doctype)
  File "apps/frappe/frappe/model/meta.py", line 63, in get_table_columns
    return frappe.db.get_table_columns(doctype)
  File "apps/frappe/frappe/database/database.py", line 1091, in get_table_columns
    columns = self.get_db_table_columns("tab" + doctype)
  File "apps/frappe/frappe/database/database.py", line 1075, in get_db_table_columns
    for r in self.sql(
  File "apps/frappe/frappe/database/database.py", line 161, in sql
    self.connect()
  File "apps/frappe/frappe/database/database.py", line 85, in connect
    self._conn = self.get_connection()
  File "apps/frappe/frappe/database/mariadb/database.py", line 76, in get_connection
    conn = pymysql.connect(
  File "env/lib/python3.8/site-packages/pymysql/connections.py", line 353, in __init__
    self.connect()
  File "env/lib/python3.8/site-packages/pymysql/connections.py", line 633, in connect
    self._request_authentication()
  File "env/lib/python3.8/site-packages/pymysql/connections.py", line 907, in _request_authentication
    auth_packet = self._read_packet()
  File "env/lib/python3.8/site-packages/pymysql/connections.py", line 725, in _read_packet
    packet.raise_for_error()
  File "env/lib/python3.8/site-packages/pymysql/protocol.py", line 221, in raise_for_error
    err.raise_mysql_exception(self._data)
  File "env/lib/python3.8/site-packages/pymysql/err.py", line 143, in raise_mysql_exception
    raise errorclass(errno, errval)
pymysql.err.OperationalError: (1045, "Access denied for user '_4859f2df50354e92'@'localhost' (using password: YES)")

Backup failed for Site ivm.com. Database or site_config.json may be corrupted
Traceback (most recent call last):
  File "apps/frappe/frappe/commands/site.py", line 592, in backup
    odb = scheduled_backup(
  File "apps/frappe/frappe/utils/backups.py", line 504, in scheduled_backup
    odb = new_backup(
  File "apps/frappe/frappe/utils/backups.py", line 538, in new_backup
    odb = BackupGenerator(
  File "apps/frappe/frappe/utils/backups.py", line 85, in __init__
    self.setup_backup_tables()
  File "apps/frappe/frappe/utils/backups.py", line 119, in setup_backup_tables
    existing_doctypes = set([x.name for x in frappe.get_all("DocType")])
  File "apps/frappe/frappe/__init__.py", line 1758, in get_all
    return get_list(doctype, *args, **kwargs)
  File "apps/frappe/frappe/__init__.py", line 1730, in get_list
    return frappe.model.db_query.DatabaseQuery(doctype).execute(*args, **kwargs)
  File "apps/frappe/frappe/model/db_query.py", line 167, in execute
    self.columns = self.get_table_columns()
  File "apps/frappe/frappe/model/db_query.py", line 441, in get_table_columns
    return get_table_columns(self.doctype)
  File "apps/frappe/frappe/model/meta.py", line 63, in get_table_columns
    return frappe.db.get_table_columns(doctype)
  File "apps/frappe/frappe/database/database.py", line 1091, in get_table_columns
    columns = self.get_db_table_columns("tab" + doctype)
  File "apps/frappe/frappe/database/database.py", line 1075, in get_db_table_columns
    for r in self.sql(
  File "apps/frappe/frappe/database/database.py", line 161, in sql
    self.connect()
  File "apps/frappe/frappe/database/database.py", line 85, in connect
    self._conn = self.get_connection()
  File "apps/frappe/frappe/database/mariadb/database.py", line 76, in get_connection
    conn = pymysql.connect(
  File "env/lib/python3.8/site-packages/pymysql/connections.py", line 353, in __init__
    self.connect()
  File "env/lib/python3.8/site-packages/pymysql/connections.py", line 633, in connect
    self._request_authentication()
  File "env/lib/python3.8/site-packages/pymysql/connections.py", line 907, in _request_authentication
    auth_packet = self._read_packet()
  File "env/lib/python3.8/site-packages/pymysql/connections.py", line 725, in _read_packet
    packet.raise_for_error()
  File "env/lib/python3.8/site-packages/pymysql/protocol.py", line 221, in raise_for_error
    err.raise_mysql_exception(self._data)
  File "env/lib/python3.8/site-packages/pymysql/err.py", line 143, in raise_mysql_exception
    raise errorclass(errno, errval)
pymysql.err.OperationalError: (1045, "Access denied for user '_4859f2df50354e92'@'localhost' (using password: YES)")

Backup failed for Site site1.local. Database or site_config.json may be corrupted
Traceback (most recent call last):
  File "apps/frappe/frappe/commands/site.py", line 592, in backup
    odb = scheduled_backup(
  File "apps/frappe/frappe/utils/backups.py", line 504, in scheduled_backup
    odb = new_backup(
  File "apps/frappe/frappe/utils/backups.py", line 538, in new_backup
    odb = BackupGenerator(
  File "apps/frappe/frappe/utils/backups.py", line 85, in __init__
    self.setup_backup_tables()
  File "apps/frappe/frappe/utils/backups.py", line 119, in setup_backup_tables
    existing_doctypes = set([x.name for x in frappe.get_all("DocType")])
  File "apps/frappe/frappe/__init__.py", line 1758, in get_all
    return get_list(doctype, *args, **kwargs)
  File "apps/frappe/frappe/__init__.py", line 1730, in get_list
    return frappe.model.db_query.DatabaseQuery(doctype).execute(*args, **kwargs)
  File "apps/frappe/frappe/model/db_query.py", line 167, in execute
    self.columns = self.get_table_columns()
  File "apps/frappe/frappe/model/db_query.py", line 441, in get_table_columns
    return get_table_columns(self.doctype)
  File "apps/frappe/frappe/model/meta.py", line 63, in get_table_columns
    return frappe.db.get_table_columns(doctype)
  File "apps/frappe/frappe/database/database.py", line 1091, in get_table_columns
    columns = self.get_db_table_columns("tab" + doctype)
  File "apps/frappe/frappe/database/database.py", line 1075, in get_db_table_columns
    for r in self.sql(
  File "apps/frappe/frappe/database/database.py", line 161, in sql
    self.connect()
  File "apps/frappe/frappe/database/database.py", line 85, in connect
    self._conn = self.get_connection()
  File "apps/frappe/frappe/database/mariadb/database.py", line 76, in get_connection
    conn = pymysql.connect(
  File "env/lib/python3.8/site-packages/pymysql/connections.py", line 353, in __init__
    self.connect()
  File "env/lib/python3.8/site-packages/pymysql/connections.py", line 633, in connect
    self._request_authentication()
  File "env/lib/python3.8/site-packages/pymysql/connections.py", line 907, in _request_authentication
    auth_packet = self._read_packet()
  File "env/lib/python3.8/site-packages/pymysql/connections.py", line 725, in _read_packet
    packet.raise_for_error()
  File "env/lib/python3.8/site-packages/pymysql/protocol.py", line 221, in raise_for_error
    err.raise_mysql_exception(self._data)
  File "env/lib/python3.8/site-packages/pymysql/err.py", line 143, in raise_mysql_exception
    raise errorclass(errno, errval)
pymysql.err.OperationalError: (1045, "Access denied for user '_4859f2df50354e92'@'localhost' (using password: YES)")

Backup failed for Site dcode.com. Database or site_config.json may be corrupted
Traceback (most recent call last):
  File "apps/frappe/frappe/commands/site.py", line 592, in backup
    odb = scheduled_backup(
  File "apps/frappe/frappe/utils/backups.py", line 504, in scheduled_backup
    odb = new_backup(
  File "apps/frappe/frappe/utils/backups.py", line 538, in new_backup
    odb = BackupGenerator(
  File "apps/frappe/frappe/utils/backups.py", line 85, in __init__
    self.setup_backup_tables()
  File "apps/frappe/frappe/utils/backups.py", line 119, in setup_backup_tables
    existing_doctypes = set([x.name for x in frappe.get_all("DocType")])
  File "apps/frappe/frappe/__init__.py", line 1758, in get_all
    return get_list(doctype, *args, **kwargs)
  File "apps/frappe/frappe/__init__.py", line 1730, in get_list
    return frappe.model.db_query.DatabaseQuery(doctype).execute(*args, **kwargs)
  File "apps/frappe/frappe/model/db_query.py", line 167, in execute
    self.columns = self.get_table_columns()
  File "apps/frappe/frappe/model/db_query.py", line 441, in get_table_columns
    return get_table_columns(self.doctype)
  File "apps/frappe/frappe/model/meta.py", line 63, in get_table_columns
    return frappe.db.get_table_columns(doctype)
  File "apps/frappe/frappe/database/database.py", line 1091, in get_table_columns
    columns = self.get_db_table_columns("tab" + doctype)
  File "apps/frappe/frappe/database/database.py", line 1075, in get_db_table_columns
    for r in self.sql(
  File "apps/frappe/frappe/database/database.py", line 161, in sql
    self.connect()
  File "apps/frappe/frappe/database/database.py", line 85, in connect
    self._conn = self.get_connection()
  File "apps/frappe/frappe/database/mariadb/database.py", line 76, in get_connection
    conn = pymysql.connect(
  File "env/lib/python3.8/site-packages/pymysql/connections.py", line 353, in __init__
    self.connect()
  File "env/lib/python3.8/site-packages/pymysql/connections.py", line 633, in connect
    self._request_authentication()
  File "env/lib/python3.8/site-packages/pymysql/connections.py", line 907, in _request_authentication
    auth_packet = self._read_packet()
  File "env/lib/python3.8/site-packages/pymysql/connections.py", line 725, in _read_packet
    packet.raise_for_error()
  File "env/lib/python3.8/site-packages/pymysql/protocol.py", line 221, in raise_for_error
    err.raise_mysql_exception(self._data)
  File "env/lib/python3.8/site-packages/pymysql/err.py", line 143, in raise_mysql_exception
    raise errorclass(errno, errval)
pymysql.err.OperationalError: (1045, "Access denied for user '_4859f2df50354e92'@'localhost' (using password: YES)")

Backup failed for Site ivm.com. Database or site_config.json may be corrupted
Traceback (most recent call last):
  File "apps/frappe/frappe/commands/site.py", line 592, in backup
    odb = scheduled_backup(
  File "apps/frappe/frappe/utils/backups.py", line 504, in scheduled_backup
    odb = new_backup(
  File "apps/frappe/frappe/utils/backups.py", line 538, in new_backup
    odb = BackupGenerator(
  File "apps/frappe/frappe/utils/backups.py", line 85, in __init__
    self.setup_backup_tables()
  File "apps/frappe/frappe/utils/backups.py", line 119, in setup_backup_tables
    existing_doctypes = set([x.name for x in frappe.get_all("DocType")])
  File "apps/frappe/frappe/__init__.py", line 1758, in get_all
    return get_list(doctype, *args, **kwargs)
  File "apps/frappe/frappe/__init__.py", line 1730, in get_list
    return frappe.model.db_query.DatabaseQuery(doctype).execute(*args, **kwargs)
  File "apps/frappe/frappe/model/db_query.py", line 167, in execute
    self.columns = self.get_table_columns()
  File "apps/frappe/frappe/model/db_query.py", line 441, in get_table_columns
    return get_table_columns(self.doctype)
  File "apps/frappe/frappe/model/meta.py", line 63, in get_table_columns
    return frappe.db.get_table_columns(doctype)
  File "apps/frappe/frappe/database/database.py", line 1091, in get_table_columns
    columns = self.get_db_table_columns("tab" + doctype)
  File "apps/frappe/frappe/database/database.py", line 1075, in get_db_table_columns
    for r in self.sql(
  File "apps/frappe/frappe/database/database.py", line 161, in sql
    self.connect()
  File "apps/frappe/frappe/database/database.py", line 85, in connect
    self._conn = self.get_connection()
  File "apps/frappe/frappe/database/mariadb/database.py", line 76, in get_connection
    conn = pymysql.connect(
  File "env/lib/python3.8/site-packages/pymysql/connections.py", line 353, in __init__
    self.connect()
  File "env/lib/python3.8/site-packages/pymysql/connections.py", line 633, in connect
    self._request_authentication()
  File "env/lib/python3.8/site-packages/pymysql/connections.py", line 907, in _request_authentication
    auth_packet = self._read_packet()
  File "env/lib/python3.8/site-packages/pymysql/connections.py", line 725, in _read_packet
    packet.raise_for_error()
  File "env/lib/python3.8/site-packages/pymysql/protocol.py", line 221, in raise_for_error
    err.raise_mysql_exception(self._data)
  File "env/lib/python3.8/site-packages/pymysql/err.py", line 143, in raise_mysql_exception
    raise errorclass(errno, errval)
pymysql.err.OperationalError: (1045, "Access denied for user '_4859f2df50354e92'@'localhost' (using password: YES)")

Backup failed for Site site1.local. Database or site_config.json may be corrupted
Traceback (most recent call last):
  File "apps/frappe/frappe/commands/site.py", line 592, in backup
    odb = scheduled_backup(
  File "apps/frappe/frappe/utils/backups.py", line 504, in scheduled_backup
    odb = new_backup(
  File "apps/frappe/frappe/utils/backups.py", line 538, in new_backup
    odb = BackupGenerator(
  File "apps/frappe/frappe/utils/backups.py", line 85, in __init__
    self.setup_backup_tables()
  File "apps/frappe/frappe/utils/backups.py", line 119, in setup_backup_tables
    existing_doctypes = set([x.name for x in frappe.get_all("DocType")])
  File "apps/frappe/frappe/__init__.py", line 1758, in get_all
    return get_list(doctype, *args, **kwargs)
  File "apps/frappe/frappe/__init__.py", line 1730, in get_list
    return frappe.model.db_query.DatabaseQuery(doctype).execute(*args, **kwargs)
  File "apps/frappe/frappe/model/db_query.py", line 167, in execute
    self.columns = self.get_table_columns()
  File "apps/frappe/frappe/model/db_query.py", line 441, in get_table_columns
    return get_table_columns(self.doctype)
  File "apps/frappe/frappe/model/meta.py", line 63, in get_table_columns
    return frappe.db.get_table_columns(doctype)
  File "apps/frappe/frappe/database/database.py", line 1091, in get_table_columns
    columns = self.get_db_table_columns("tab" + doctype)
  File "apps/frappe/frappe/database/database.py", line 1075, in get_db_table_columns
    for r in self.sql(
  File "apps/frappe/frappe/database/database.py", line 161, in sql
    self.connect()
  File "apps/frappe/frappe/database/database.py", line 85, in connect
    self._conn = self.get_connection()
  File "apps/frappe/frappe/database/mariadb/database.py", line 76, in get_connection
    conn = pymysql.connect(
  File "env/lib/python3.8/site-packages/pymysql/connections.py", line 353, in __init__
    self.connect()
  File "env/lib/python3.8/site-packages/pymysql/connections.py", line 633, in connect
    self._request_authentication()
  File "env/lib/python3.8/site-packages/pymysql/connections.py", line 907, in _request_authentication
    auth_packet = self._read_packet()
  File "env/lib/python3.8/site-packages/pymysql/connections.py", line 725, in _read_packet
    packet.raise_for_error()
  File "env/lib/python3.8/site-packages/pymysql/protocol.py", line 221, in raise_for_error
    err.raise_mysql_exception(self._data)
  File "env/lib/python3.8/site-packages/pymysql/err.py", line 143, in raise_mysql_exception
    raise errorclass(errno, errval)
pymysql.err.OperationalError: (1045, "Access denied for user '_4859f2df50354e92'@'localhost' (using password: YES)")

Backup failed for Site dcode.com. Database or site_config.json may be corrupted
Traceback (most recent call last):
  File "apps/frappe/frappe/commands/site.py", line 592, in backup
    odb = scheduled_backup(
  File "apps/frappe/frappe/utils/backups.py", line 504, in scheduled_backup
    odb = new_backup(
  File "apps/frappe/frappe/utils/backups.py", line 538, in new_backup
    odb = BackupGenerator(
  File "apps/frappe/frappe/utils/backups.py", line 85, in __init__
    self.setup_backup_tables()
  File "apps/frappe/frappe/utils/backups.py", line 119, in setup_backup_tables
    existing_doctypes = set([x.name for x in frappe.get_all("DocType")])
  File "apps/frappe/frappe/__init__.py", line 1758, in get_all
    return get_list(doctype, *args, **kwargs)
  File "apps/frappe/frappe/__init__.py", line 1730, in get_list
    return frappe.model.db_query.DatabaseQuery(doctype).execute(*args, **kwargs)
  File "apps/frappe/frappe/model/db_query.py", line 167, in execute
    self.columns = self.get_table_columns()
  File "apps/frappe/frappe/model/db_query.py", line 441, in get_table_columns
    return get_table_columns(self.doctype)
  File "apps/frappe/frappe/model/meta.py", line 63, in get_table_columns
    return frappe.db.get_table_columns(doctype)
  File "apps/frappe/frappe/database/database.py", line 1091, in get_table_columns
    columns = self.get_db_table_columns("tab" + doctype)
  File "apps/frappe/frappe/database/database.py", line 1075, in get_db_table_columns
    for r in self.sql(
  File "apps/frappe/frappe/database/database.py", line 161, in sql
    self.connect()
  File "apps/frappe/frappe/database/database.py", line 85, in connect
    self._conn = self.get_connection()
  File "apps/frappe/frappe/database/mariadb/database.py", line 76, in get_connection
    conn = pymysql.connect(
  File "env/lib/python3.8/site-packages/pymysql/connections.py", line 353, in __init__
    self.connect()
  File "env/lib/python3.8/site-packages/pymysql/connections.py", line 633, in connect
    self._request_authentication()
  File "env/lib/python3.8/site-packages/pymysql/connections.py", line 907, in _request_authentication
    auth_packet = self._read_packet()
  File "env/lib/python3.8/site-packages/pymysql/connections.py", line 725, in _read_packet
    packet.raise_for_error()
  File "env/lib/python3.8/site-packages/pymysql/protocol.py", line 221, in raise_for_error
    err.raise_mysql_exception(self._data)
  File "env/lib/python3.8/site-packages/pymysql/err.py", line 143, in raise_mysql_exception
    raise errorclass(errno, errval)
pymysql.err.OperationalError: (1045, "Access denied for user '_4859f2df50354e92'@'localhost' (using password: YES)")

Backup failed for Site ivm.com. Database or site_config.json may be corrupted
Traceback (most recent call last):
  File "apps/frappe/frappe/commands/site.py", line 592, in backup
    odb = scheduled_backup(
  File "apps/frappe/frappe/utils/backups.py", line 504, in scheduled_backup
    odb = new_backup(
  File "apps/frappe/frappe/utils/backups.py", line 538, in new_backup
    odb = BackupGenerator(
  File "apps/frappe/frappe/utils/backups.py", line 85, in __init__
    self.setup_backup_tables()
  File "apps/frappe/frappe/utils/backups.py", line 119, in setup_backup_tables
    existing_doctypes = set([x.name for x in frappe.get_all("DocType")])
  File "apps/frappe/frappe/__init__.py", line 1758, in get_all
    return get_list(doctype, *args, **kwargs)
  File "apps/frappe/frappe/__init__.py", line 1730, in get_list
    return frappe.model.db_query.DatabaseQuery(doctype).execute(*args, **kwargs)
  File "apps/frappe/frappe/model/db_query.py", line 167, in execute
    self.columns = self.get_table_columns()
  File "apps/frappe/frappe/model/db_query.py", line 441, in get_table_columns
    return get_table_columns(self.doctype)
  File "apps/frappe/frappe/model/meta.py", line 63, in get_table_columns
    return frappe.db.get_table_columns(doctype)
  File "apps/frappe/frappe/database/database.py", line 1091, in get_table_columns
    columns = self.get_db_table_columns("tab" + doctype)
  File "apps/frappe/frappe/database/database.py", line 1075, in get_db_table_columns
    for r in self.sql(
  File "apps/frappe/frappe/database/database.py", line 161, in sql
    self.connect()
  File "apps/frappe/frappe/database/database.py", line 85, in connect
    self._conn = self.get_connection()
  File "apps/frappe/frappe/database/mariadb/database.py", line 76, in get_connection
    conn = pymysql.connect(
  File "env/lib/python3.8/site-packages/pymysql/connections.py", line 353, in __init__
    self.connect()
  File "env/lib/python3.8/site-packages/pymysql/connections.py", line 633, in connect
    self._request_authentication()
  File "env/lib/python3.8/site-packages/pymysql/connections.py", line 907, in _request_authentication
    auth_packet = self._read_packet()
  File "env/lib/python3.8/site-packages/pymysql/connections.py", line 725, in _read_packet
    packet.raise_for_error()
  File "env/lib/python3.8/site-packages/pymysql/protocol.py", line 221, in raise_for_error
    err.raise_mysql_exception(self._data)
  File "env/lib/python3.8/site-packages/pymysql/err.py", line 143, in raise_mysql_exception
    raise errorclass(errno, errval)
pymysql.err.OperationalError: (1045, "Access denied for user '_4859f2df50354e92'@'localhost' (using password: YES)")

Backup failed for Site site1.local. Database or site_config.json may be corrupted
Traceback (most recent call last):
  File "apps/frappe/frappe/commands/site.py", line 592, in backup
    odb = scheduled_backup(
  File "apps/frappe/frappe/utils/backups.py", line 504, in scheduled_backup
    odb = new_backup(
  File "apps/frappe/frappe/utils/backups.py", line 538, in new_backup
    odb = BackupGenerator(
  File "apps/frappe/frappe/utils/backups.py", line 85, in __init__
    self.setup_backup_tables()
  File "apps/frappe/frappe/utils/backups.py", line 119, in setup_backup_tables
    existing_doctypes = set([x.name for x in frappe.get_all("DocType")])
  File "apps/frappe/frappe/__init__.py", line 1758, in get_all
    return get_list(doctype, *args, **kwargs)
  File "apps/frappe/frappe/__init__.py", line 1730, in get_list
    return frappe.model.db_query.DatabaseQuery(doctype).execute(*args, **kwargs)
  File "apps/frappe/frappe/model/db_query.py", line 167, in execute
    self.columns = self.get_table_columns()
  File "apps/frappe/frappe/model/db_query.py", line 441, in get_table_columns
    return get_table_columns(self.doctype)
  File "apps/frappe/frappe/model/meta.py", line 63, in get_table_columns
    return frappe.db.get_table_columns(doctype)
  File "apps/frappe/frappe/database/database.py", line 1091, in get_table_columns
    columns = self.get_db_table_columns("tab" + doctype)
  File "apps/frappe/frappe/database/database.py", line 1075, in get_db_table_columns
    for r in self.sql(
  File "apps/frappe/frappe/database/database.py", line 161, in sql
    self.connect()
  File "apps/frappe/frappe/database/database.py", line 85, in connect
    self._conn = self.get_connection()
  File "apps/frappe/frappe/database/mariadb/database.py", line 76, in get_connection
    conn = pymysql.connect(
  File "env/lib/python3.8/site-packages/pymysql/connections.py", line 353, in __init__
    self.connect()
  File "env/lib/python3.8/site-packages/pymysql/connections.py", line 633, in connect
    self._request_authentication()
  File "env/lib/python3.8/site-packages/pymysql/connections.py", line 907, in _request_authentication
    auth_packet = self._read_packet()
  File "env/lib/python3.8/site-packages/pymysql/connections.py", line 725, in _read_packet
    packet.raise_for_error()
  File "env/lib/python3.8/site-packages/pymysql/protocol.py", line 221, in raise_for_error
    err.raise_mysql_exception(self._data)
  File "env/lib/python3.8/site-packages/pymysql/err.py", line 143, in raise_mysql_exception
    raise errorclass(errno, errval)
pymysql.err.OperationalError: (1045, "Access denied for user '_4859f2df50354e92'@'localhost' (using password: YES)")

Backup failed for Site dcode.com. Database or site_config.json may be corrupted
Traceback (most recent call last):
  File "apps/frappe/frappe/commands/site.py", line 592, in backup
    odb = scheduled_backup(
  File "apps/frappe/frappe/utils/backups.py", line 504, in scheduled_backup
    odb = new_backup(
  File "apps/frappe/frappe/utils/backups.py", line 538, in new_backup
    odb = BackupGenerator(
  File "apps/frappe/frappe/utils/backups.py", line 85, in __init__
    self.setup_backup_tables()
  File "apps/frappe/frappe/utils/backups.py", line 119, in setup_backup_tables
    existing_doctypes = set([x.name for x in frappe.get_all("DocType")])
  File "apps/frappe/frappe/__init__.py", line 1758, in get_all
    return get_list(doctype, *args, **kwargs)
  File "apps/frappe/frappe/__init__.py", line 1730, in get_list
    return frappe.model.db_query.DatabaseQuery(doctype).execute(*args, **kwargs)
  File "apps/frappe/frappe/model/db_query.py", line 167, in execute
    self.columns = self.get_table_columns()
  File "apps/frappe/frappe/model/db_query.py", line 441, in get_table_columns
    return get_table_columns(self.doctype)
  File "apps/frappe/frappe/model/meta.py", line 63, in get_table_columns
    return frappe.db.get_table_columns(doctype)
  File "apps/frappe/frappe/database/database.py", line 1091, in get_table_columns
    columns = self.get_db_table_columns("tab" + doctype)
  File "apps/frappe/frappe/database/database.py", line 1075, in get_db_table_columns
    for r in self.sql(
  File "apps/frappe/frappe/database/database.py", line 161, in sql
    self.connect()
  File "apps/frappe/frappe/database/database.py", line 85, in connect
    self._conn = self.get_connection()
  File "apps/frappe/frappe/database/mariadb/database.py", line 76, in get_connection
    conn = pymysql.connect(
  File "env/lib/python3.8/site-packages/pymysql/connections.py", line 353, in __init__
    self.connect()
  File "env/lib/python3.8/site-packages/pymysql/connections.py", line 633, in connect
    self._request_authentication()
  File "env/lib/python3.8/site-packages/pymysql/connections.py", line 907, in _request_authentication
    auth_packet = self._read_packet()
  File "env/lib/python3.8/site-packages/pymysql/connections.py", line 725, in _read_packet
    packet.raise_for_error()
  File "env/lib/python3.8/site-packages/pymysql/protocol.py", line 221, in raise_for_error
    err.raise_mysql_exception(self._data)
  File "env/lib/python3.8/site-packages/pymysql/err.py", line 143, in raise_mysql_exception
    raise errorclass(errno, errval)
pymysql.err.OperationalError: (1045, "Access denied for user '_4859f2df50354e92'@'localhost' (using password: YES)")

Backup failed for Site ivm.com. Database or site_config.json may be corrupted
Traceback (most recent call last):
  File "apps/frappe/frappe/commands/site.py", line 592, in backup
    odb = scheduled_backup(
  File "apps/frappe/frappe/utils/backups.py", line 504, in scheduled_backup
    odb = new_backup(
  File "apps/frappe/frappe/utils/backups.py", line 538, in new_backup
    odb = BackupGenerator(
  File "apps/frappe/frappe/utils/backups.py", line 85, in __init__
    self.setup_backup_tables()
  File "apps/frappe/frappe/utils/backups.py", line 119, in setup_backup_tables
    existing_doctypes = set([x.name for x in frappe.get_all("DocType")])
  File "apps/frappe/frappe/__init__.py", line 1758, in get_all
    return get_list(doctype, *args, **kwargs)
  File "apps/frappe/frappe/__init__.py", line 1730, in get_list
    return frappe.model.db_query.DatabaseQuery(doctype).execute(*args, **kwargs)
  File "apps/frappe/frappe/model/db_query.py", line 167, in execute
    self.columns = self.get_table_columns()
  File "apps/frappe/frappe/model/db_query.py", line 441, in get_table_columns
    return get_table_columns(self.doctype)
  File "apps/frappe/frappe/model/meta.py", line 63, in get_table_columns
    return frappe.db.get_table_columns(doctype)
  File "apps/frappe/frappe/database/database.py", line 1091, in get_table_columns
    columns = self.get_db_table_columns("tab" + doctype)
  File "apps/frappe/frappe/database/database.py", line 1075, in get_db_table_columns
    for r in self.sql(
  File "apps/frappe/frappe/database/database.py", line 161, in sql
    self.connect()
  File "apps/frappe/frappe/database/database.py", line 85, in connect
    self._conn = self.get_connection()
  File "apps/frappe/frappe/database/mariadb/database.py", line 76, in get_connection
    conn = pymysql.connect(
  File "env/lib/python3.8/site-packages/pymysql/connections.py", line 353, in __init__
    self.connect()
  File "env/lib/python3.8/site-packages/pymysql/connections.py", line 633, in connect
    self._request_authentication()
  File "env/lib/python3.8/site-packages/pymysql/connections.py", line 907, in _request_authentication
    auth_packet = self._read_packet()
  File "env/lib/python3.8/site-packages/pymysql/connections.py", line 725, in _read_packet
    packet.raise_for_error()
  File "env/lib/python3.8/site-packages/pymysql/protocol.py", line 221, in raise_for_error
    err.raise_mysql_exception(self._data)
  File "env/lib/python3.8/site-packages/pymysql/err.py", line 143, in raise_mysql_exception
    raise errorclass(errno, errval)
pymysql.err.OperationalError: (1045, "Access denied for user '_4859f2df50354e92'@'localhost' (using password: YES)")

Backup failed for Site site1.local. Database or site_config.json may be corrupted
Traceback (most recent call last):
  File "apps/frappe/frappe/commands/site.py", line 592, in backup
    odb = scheduled_backup(
  File "apps/frappe/frappe/utils/backups.py", line 504, in scheduled_backup
    odb = new_backup(
  File "apps/frappe/frappe/utils/backups.py", line 538, in new_backup
    odb = BackupGenerator(
  File "apps/frappe/frappe/utils/backups.py", line 85, in __init__
    self.setup_backup_tables()
  File "apps/frappe/frappe/utils/backups.py", line 119, in setup_backup_tables
    existing_doctypes = set([x.name for x in frappe.get_all("DocType")])
  File "apps/frappe/frappe/__init__.py", line 1758, in get_all
    return get_list(doctype, *args, **kwargs)
  File "apps/frappe/frappe/__init__.py", line 1730, in get_list
    return frappe.model.db_query.DatabaseQuery(doctype).execute(*args, **kwargs)
  File "apps/frappe/frappe/model/db_query.py", line 167, in execute
    self.columns = self.get_table_columns()
  File "apps/frappe/frappe/model/db_query.py", line 441, in get_table_columns
    return get_table_columns(self.doctype)
  File "apps/frappe/frappe/model/meta.py", line 63, in get_table_columns
    return frappe.db.get_table_columns(doctype)
  File "apps/frappe/frappe/database/database.py", line 1091, in get_table_columns
    columns = self.get_db_table_columns("tab" + doctype)
  File "apps/frappe/frappe/database/database.py", line 1075, in get_db_table_columns
    for r in self.sql(
  File "apps/frappe/frappe/database/database.py", line 161, in sql
    self.connect()
  File "apps/frappe/frappe/database/database.py", line 85, in connect
    self._conn = self.get_connection()
  File "apps/frappe/frappe/database/mariadb/database.py", line 76, in get_connection
    conn = pymysql.connect(
  File "env/lib/python3.8/site-packages/pymysql/connections.py", line 353, in __init__
    self.connect()
  File "env/lib/python3.8/site-packages/pymysql/connections.py", line 633, in connect
    self._request_authentication()
  File "env/lib/python3.8/site-packages/pymysql/connections.py", line 907, in _request_authentication
    auth_packet = self._read_packet()
  File "env/lib/python3.8/site-packages/pymysql/connections.py", line 725, in _read_packet
    packet.raise_for_error()
  File "env/lib/python3.8/site-packages/pymysql/protocol.py", line 221, in raise_for_error
    err.raise_mysql_exception(self._data)
  File "env/lib/python3.8/site-packages/pymysql/err.py", line 143, in raise_mysql_exception
    raise errorclass(errno, errval)
pymysql.err.OperationalError: (1045, "Access denied for user '_4859f2df50354e92'@'localhost' (using password: YES)")

